Rasa process starting
Rasa process starting
Rasa process starting
Added 'nlp_spacy' to component cache. Key 'nlp_spacy-en'.
C:\Users\AndresArciniegas\AppData\Roaming\Python\Python36\site-packages\rasa_nlu\extractors\entity_synonyms.py:85: UserWarning: Failed to load synonyms file from 'models/nlu/default/nursenlu\entity_synonyms.json'
  "".format(entity_synonyms_file))

D:\ProgramFiles\Anaconda3\envs\envbot\lib\site-packages\pykwalify\core.py:99: UnsafeLoaderWarning: 
The default 'Loader' for 'load(stream)' without further arguments can be unsafe.
Use 'load(stream, Loader=ruamel.yaml.Loader)' explicitly if that is OK.
Alternatively include the following in your code:

  import warnings
  warnings.simplefilter('ignore', ruamel.yaml.error.UnsafeLoaderWarning)

In most other cases you should consider using 'safe_load(stream)'
  data = yaml.load(stream)

Available web server routes: 
static                                             GET, OPTIONS, HEAD             /static/[filename]
custom_webhook_CmdlineInput.health                 GET, OPTIONS, HEAD             /webhooks/rest/
custom_webhook_CmdlineInput.receive                POST, OPTIONS                  /webhooks/rest/webhook
Rasa Core server is up and running on http://localhost:5005
Creating a new tracker for id 'default'.
C:\Users\AndresArciniegas\AppData\Roaming\Python\Python36\site-packages\sklearn\preprocessing\label.py:151: DeprecationWarning: The truth value of an empty array is ambiguous. Returning False, but in future this will result in an error. Use `array.size > 0` to check that an array is not empty.
  if diff:

Received user message 'Hello' with intent '{'name': 'greet', 'confidence': 0.6280013948232969}' and entities '[]'
Logged UserUtterance - tracker now has 2 events
Current slot values: 
	location: None
	object: None
Current tracker state [{}, {'prev_action_listen': 1.0, 'intent_greet': 1.0}]
There is a memorised next action '5'
Predicted next action using policy_0_MemoizationPolicy
Predicted next action 'utter_greet' with prob 1.00.
Action 'utter_greet' ended with events '[]'
Bot utterance 'BotUttered(text: Hello! You can call me Nurse. How can I help you?, data: {
  "elements": null,
  "buttons": null,
  "attachment": null
})'
Current tracker state [{'prev_action_listen': 1.0, 'intent_greet': 1.0}, {'prev_utter_greet': 1.0, 'intent_greet': 1.0}]
There is a memorised next action '0'
Predicted next action using policy_0_MemoizationPolicy
Predicted next action 'action_listen' with prob 1.00.
Action 'action_listen' ended with events '[]'
Recreating tracker for id 'default'
C:\Users\AndresArciniegas\AppData\Roaming\Python\Python36\site-packages\sklearn\preprocessing\label.py:151: DeprecationWarning: The truth value of an empty array is ambiguous. Returning False, but in future this will result in an error. Use `array.size > 0` to check that an array is not empty.
  if diff:

Received user message 'Tell me a joke' with intent '{'name': 'joke', 'confidence': 0.6094320004912319}' and entities '[]'
Logged UserUtterance - tracker now has 6 events
Current slot values: 
	location: None
	object: None
Current tracker state [{'prev_utter_greet': 1.0, 'intent_greet': 1.0}, {'intent_joke': 1.0, 'prev_action_listen': 1.0}]
There is a memorised next action '9'
Predicted next action using policy_0_MemoizationPolicy
Predicted next action 'action_joke' with prob 1.00.
Encountered an exception while running action 'action_joke'. Bot will continue, but the actions events are lost. Make sure to fix the exception in your custom code.
The model predicted the custom action 'action_joke' but you didn't configure an endpoint to run this custom action. Please take a look at the docs and set an endpoint configuration. https://rasa.com/docs/core/customactions/
Traceback (most recent call last):
  File "C:\Users\AndresArciniegas\AppData\Roaming\Python\Python36\site-packages\rasa_core\processor.py", line 351, in _run_action
    events = action.run(dispatcher, tracker, self.domain)
  File "C:\Users\AndresArciniegas\AppData\Roaming\Python\Python36\site-packages\rasa_core\actions\action.py", line 321, in run
    "".format(self.name(), DOCS_BASE_URL))
Exception: The model predicted the custom action 'action_joke' but you didn't configure an endpoint to run this custom action. Please take a look at the docs and set an endpoint configuration. https://rasa.com/docs/core/customactions/
Action 'action_joke' ended with events '[]'
Current tracker state [{'intent_joke': 1.0, 'prev_action_listen': 1.0}, {'intent_joke': 1.0, 'prev_action_joke': 1.0}]
There is a memorised next action '0'
Predicted next action using policy_0_MemoizationPolicy
Predicted next action 'action_listen' with prob 1.00.
Action 'action_listen' ended with events '[]'
Rasa process starting
Added 'nlp_spacy' to component cache. Key 'nlp_spacy-en'.
C:\Users\AndresArciniegas\AppData\Roaming\Python\Python36\site-packages\rasa_nlu\extractors\entity_synonyms.py:85: UserWarning: Failed to load synonyms file from 'models/nlu/default/nursenlu\entity_synonyms.json'
  "".format(entity_synonyms_file))

D:\ProgramFiles\Anaconda3\envs\envbot\lib\site-packages\pykwalify\core.py:99: UnsafeLoaderWarning: 
The default 'Loader' for 'load(stream)' without further arguments can be unsafe.
Use 'load(stream, Loader=ruamel.yaml.Loader)' explicitly if that is OK.
Alternatively include the following in your code:

  import warnings
  warnings.simplefilter('ignore', ruamel.yaml.error.UnsafeLoaderWarning)

In most other cases you should consider using 'safe_load(stream)'
  data = yaml.load(stream)

Available web server routes: 
static                                             GET, OPTIONS, HEAD             /static/[filename]
custom_webhook_CmdlineInput.health                 GET, OPTIONS, HEAD             /webhooks/rest/
custom_webhook_CmdlineInput.receive                OPTIONS, POST                  /webhooks/rest/webhook
Rasa Core server is up and running on http://localhost:5005
Creating a new tracker for id 'default'.
C:\Users\AndresArciniegas\AppData\Roaming\Python\Python36\site-packages\sklearn\preprocessing\label.py:151: DeprecationWarning: The truth value of an empty array is ambiguous. Returning False, but in future this will result in an error. Use `array.size > 0` to check that an array is not empty.
  if diff:

Received user message 'Hello!' with intent '{'name': 'greet', 'confidence': 0.35399536066363413}' and entities '[]'
Logged UserUtterance - tracker now has 2 events
Current slot values: 
	location: None
	object: None
Current tracker state [{}, {'intent_greet': 1.0, 'prev_action_listen': 1.0}]
There is a memorised next action '5'
Predicted next action using policy_0_MemoizationPolicy
Predicted next action 'utter_greet' with prob 1.00.
Action 'utter_greet' ended with events '[]'
Bot utterance 'BotUttered(text: Hello human! You can call me Nurse. What can I do for you?., data: {
  "elements": null,
  "buttons": null,
  "attachment": null
})'
Current tracker state [{'intent_greet': 1.0, 'prev_action_listen': 1.0}, {'prev_utter_greet': 1.0, 'intent_greet': 1.0}]
There is a memorised next action '0'
Predicted next action using policy_0_MemoizationPolicy
Predicted next action 'action_listen' with prob 1.00.
Action 'action_listen' ended with events '[]'
Recreating tracker for id 'default'
C:\Users\AndresArciniegas\AppData\Roaming\Python\Python36\site-packages\sklearn\preprocessing\label.py:151: DeprecationWarning: The truth value of an empty array is ambiguous. Returning False, but in future this will result in an error. Use `array.size > 0` to check that an array is not empty.
  if diff:

Received user message 'Tell me a joke' with intent '{'name': 'joke', 'confidence': 0.6094320004912319}' and entities '[]'
Logged UserUtterance - tracker now has 6 events
Current slot values: 
	location: None
	object: None
Current tracker state [{'prev_utter_greet': 1.0, 'intent_greet': 1.0}, {'intent_joke': 1.0, 'prev_action_listen': 1.0}]
There is a memorised next action '9'
Predicted next action using policy_0_MemoizationPolicy
Predicted next action 'action_joke' with prob 1.00.
Encountered an exception while running action 'action_joke'. Bot will continue, but the actions events are lost. Make sure to fix the exception in your custom code.
The model predicted the custom action 'action_joke' but you didn't configure an endpoint to run this custom action. Please take a look at the docs and set an endpoint configuration. https://rasa.com/docs/core/customactions/
Traceback (most recent call last):
  File "C:\Users\AndresArciniegas\AppData\Roaming\Python\Python36\site-packages\rasa_core\processor.py", line 351, in _run_action
    events = action.run(dispatcher, tracker, self.domain)
  File "C:\Users\AndresArciniegas\AppData\Roaming\Python\Python36\site-packages\rasa_core\actions\action.py", line 321, in run
    "".format(self.name(), DOCS_BASE_URL))
Exception: The model predicted the custom action 'action_joke' but you didn't configure an endpoint to run this custom action. Please take a look at the docs and set an endpoint configuration. https://rasa.com/docs/core/customactions/
Action 'action_joke' ended with events '[]'
Current tracker state [{'intent_joke': 1.0, 'prev_action_listen': 1.0}, {'intent_joke': 1.0, 'prev_action_joke': 1.0}]
There is a memorised next action '0'
Predicted next action using policy_0_MemoizationPolicy
Predicted next action 'action_listen' with prob 1.00.
Action 'action_listen' ended with events '[]'
Recreating tracker for id 'default'
C:\Users\AndresArciniegas\AppData\Roaming\Python\Python36\site-packages\sklearn\preprocessing\label.py:151: DeprecationWarning: The truth value of an empty array is ambiguous. Returning False, but in future this will result in an error. Use `array.size > 0` to check that an array is not empty.
  if diff:

Received user message 'stop' with intent '{'name': 'goodbye', 'confidence': 0.43645630946090896}' and entities '[]'
Logged UserUtterance - tracker now has 9 events
Current slot values: 
	location: None
	object: None
Current tracker state [{'intent_joke': 1.0, 'prev_action_joke': 1.0}, {'intent_goodbye': 1.0, 'prev_action_listen': 1.0}]
There is a memorised next action '7'
Predicted next action using policy_0_MemoizationPolicy
Predicted next action 'utter_standby' with prob 1.00.
Action 'utter_standby' ended with events '[]'
Bot utterance 'BotUttered(text: I'm at your service., data: {
  "elements": null,
  "buttons": null,
  "attachment": null
})'
Current tracker state [{'intent_goodbye': 1.0, 'prev_action_listen': 1.0}, {'intent_goodbye': 1.0, 'prev_utter_standby': 1.0}]
There is a memorised next action '0'
Predicted next action using policy_0_MemoizationPolicy
Predicted next action 'action_listen' with prob 1.00.
Action 'action_listen' ended with events '[]'
Rasa process starting
Added 'nlp_spacy' to component cache. Key 'nlp_spacy-en'.
C:\Users\AndresArciniegas\AppData\Roaming\Python\Python36\site-packages\rasa_nlu\extractors\entity_synonyms.py:85: UserWarning: Failed to load synonyms file from 'models/nlu/default/nursenlu\entity_synonyms.json'
  "".format(entity_synonyms_file))

D:\ProgramFiles\Anaconda3\envs\envbot\lib\site-packages\pykwalify\core.py:99: UnsafeLoaderWarning: 
The default 'Loader' for 'load(stream)' without further arguments can be unsafe.
Use 'load(stream, Loader=ruamel.yaml.Loader)' explicitly if that is OK.
Alternatively include the following in your code:

  import warnings
  warnings.simplefilter('ignore', ruamel.yaml.error.UnsafeLoaderWarning)

In most other cases you should consider using 'safe_load(stream)'
  data = yaml.load(stream)

Available web server routes: 
static                                             GET, OPTIONS, HEAD             /static/[filename]
custom_webhook_CmdlineInput.health                 GET, OPTIONS, HEAD             /webhooks/rest/
custom_webhook_CmdlineInput.receive                POST, OPTIONS                  /webhooks/rest/webhook
Rasa Core server is up and running on http://localhost:5005
Creating a new tracker for id 'default'.
C:\Users\AndresArciniegas\AppData\Roaming\Python\Python36\site-packages\sklearn\preprocessing\label.py:151: DeprecationWarning: The truth value of an empty array is ambiguous. Returning False, but in future this will result in an error. Use `array.size > 0` to check that an array is not empty.
  if diff:

Received user message 'Hello' with intent '{'name': 'greet', 'confidence': 0.6280013948232969}' and entities '[]'
Logged UserUtterance - tracker now has 2 events
Current slot values: 
	location: None
	object: None
Current tracker state [{}, {'intent_greet': 1.0, 'prev_action_listen': 1.0}]
There is a memorised next action '5'
Predicted next action using policy_0_MemoizationPolicy
Predicted next action 'utter_greet' with prob 1.00.
Action 'utter_greet' ended with events '[]'
Bot utterance 'BotUttered(text: Hello human! You can call me Nurse. What can I do for you?., data: {
  "elements": null,
  "buttons": null,
  "attachment": null
})'
Current tracker state [{'intent_greet': 1.0, 'prev_action_listen': 1.0}, {'intent_greet': 1.0, 'prev_utter_greet': 1.0}]
There is a memorised next action '0'
Predicted next action using policy_0_MemoizationPolicy
Predicted next action 'action_listen' with prob 1.00.
Action 'action_listen' ended with events '[]'
Recreating tracker for id 'default'
C:\Users\AndresArciniegas\AppData\Roaming\Python\Python36\site-packages\sklearn\preprocessing\label.py:151: DeprecationWarning: The truth value of an empty array is ambiguous. Returning False, but in future this will result in an error. Use `array.size > 0` to check that an array is not empty.
  if diff:

Received user message 'I need a joke' with intent '{'name': 'joke', 'confidence': 0.5337240033575549}' and entities '[]'
Logged UserUtterance - tracker now has 6 events
Current slot values: 
	location: None
	object: None
Current tracker state [{'intent_greet': 1.0, 'prev_utter_greet': 1.0}, {'intent_joke': 1.0, 'prev_action_listen': 1.0}]
There is a memorised next action '9'
Predicted next action using policy_0_MemoizationPolicy
Predicted next action 'action_joke' with prob 1.00.
Calling action endpoint to run action 'action_joke'.
Failed to run custom action 'action_joke'. Couldn't connect to the server at 'http://localhost:5055/webhook'. Is the server running? Error: HTTPConnectionPool(host='localhost', port=5055): Max retries exceeded with url: /webhook (Caused by NewConnectionError('<urllib3.connection.HTTPConnection object at 0x0000025A35459B00>: Failed to establish a new connection: [WinError 10061] No connection could be made because the target machine actively refused it',))
Encountered an exception while running action 'action_joke'. Bot will continue, but the actions events are lost. Make sure to fix the exception in your custom code.
Failed to execute custom action.
Traceback (most recent call last):
  File "D:\ProgramFiles\Anaconda3\envs\envbot\lib\site-packages\urllib3\connection.py", line 171, in _new_conn
    (self._dns_host, self.port), self.timeout, **extra_kw)
  File "D:\ProgramFiles\Anaconda3\envs\envbot\lib\site-packages\urllib3\util\connection.py", line 79, in create_connection
    raise err
  File "D:\ProgramFiles\Anaconda3\envs\envbot\lib\site-packages\urllib3\util\connection.py", line 69, in create_connection
    sock.connect(sa)
ConnectionRefusedError: [WinError 10061] No connection could be made because the target machine actively refused it

During handling of the above exception, another exception occurred:

Traceback (most recent call last):
  File "D:\ProgramFiles\Anaconda3\envs\envbot\lib\site-packages\urllib3\connectionpool.py", line 600, in urlopen
    chunked=chunked)
  File "D:\ProgramFiles\Anaconda3\envs\envbot\lib\site-packages\urllib3\connectionpool.py", line 354, in _make_request
    conn.request(method, url, **httplib_request_kw)
  File "D:\ProgramFiles\Anaconda3\envs\envbot\lib\http\client.py", line 1239, in request
    self._send_request(method, url, body, headers, encode_chunked)
  File "D:\ProgramFiles\Anaconda3\envs\envbot\lib\http\client.py", line 1285, in _send_request
    self.endheaders(body, encode_chunked=encode_chunked)
  File "D:\ProgramFiles\Anaconda3\envs\envbot\lib\http\client.py", line 1234, in endheaders
    self._send_output(message_body, encode_chunked=encode_chunked)
  File "D:\ProgramFiles\Anaconda3\envs\envbot\lib\http\client.py", line 1026, in _send_output
    self.send(msg)
  File "D:\ProgramFiles\Anaconda3\envs\envbot\lib\http\client.py", line 964, in send
    self.connect()
  File "D:\ProgramFiles\Anaconda3\envs\envbot\lib\site-packages\urllib3\connection.py", line 196, in connect
    conn = self._new_conn()
  File "D:\ProgramFiles\Anaconda3\envs\envbot\lib\site-packages\urllib3\connection.py", line 180, in _new_conn
    self, "Failed to establish a new connection: %s" % e)
urllib3.exceptions.NewConnectionError: <urllib3.connection.HTTPConnection object at 0x0000025A35459B00>: Failed to establish a new connection: [WinError 10061] No connection could be made because the target machine actively refused it

During handling of the above exception, another exception occurred:

Traceback (most recent call last):
  File "D:\ProgramFiles\Anaconda3\envs\envbot\lib\site-packages\requests\adapters.py", line 449, in send
    timeout=timeout
  File "D:\ProgramFiles\Anaconda3\envs\envbot\lib\site-packages\urllib3\connectionpool.py", line 638, in urlopen
    _stacktrace=sys.exc_info()[2])
  File "D:\ProgramFiles\Anaconda3\envs\envbot\lib\site-packages\urllib3\util\retry.py", line 398, in increment
    raise MaxRetryError(_pool, url, error or ResponseError(cause))
urllib3.exceptions.MaxRetryError: HTTPConnectionPool(host='localhost', port=5055): Max retries exceeded with url: /webhook (Caused by NewConnectionError('<urllib3.connection.HTTPConnection object at 0x0000025A35459B00>: Failed to establish a new connection: [WinError 10061] No connection could be made because the target machine actively refused it',))

During handling of the above exception, another exception occurred:

Traceback (most recent call last):
  File "C:\Users\AndresArciniegas\AppData\Roaming\Python\Python36\site-packages\rasa_core\actions\action.py", line 327, in run
    json=json, method="post", timeout=DEFAULT_REQUEST_TIMEOUT)
  File "C:\Users\AndresArciniegas\AppData\Roaming\Python\Python36\site-packages\rasa_core\utils.py", line 748, in request
    **kwargs)
  File "D:\ProgramFiles\Anaconda3\envs\envbot\lib\site-packages\requests\api.py", line 60, in request
    return session.request(method=method, url=url, **kwargs)
  File "D:\ProgramFiles\Anaconda3\envs\envbot\lib\site-packages\requests\sessions.py", line 524, in request
    resp = self.send(prep, **send_kwargs)
  File "D:\ProgramFiles\Anaconda3\envs\envbot\lib\site-packages\requests\sessions.py", line 637, in send
    r = adapter.send(request, **kwargs)
  File "D:\ProgramFiles\Anaconda3\envs\envbot\lib\site-packages\requests\adapters.py", line 516, in send
    raise ConnectionError(e, request=request)
requests.exceptions.ConnectionError: HTTPConnectionPool(host='localhost', port=5055): Max retries exceeded with url: /webhook (Caused by NewConnectionError('<urllib3.connection.HTTPConnection object at 0x0000025A35459B00>: Failed to establish a new connection: [WinError 10061] No connection could be made because the target machine actively refused it',))

During handling of the above exception, another exception occurred:

Traceback (most recent call last):
  File "C:\Users\AndresArciniegas\AppData\Roaming\Python\Python36\site-packages\rasa_core\processor.py", line 351, in _run_action
    events = action.run(dispatcher, tracker, self.domain)
  File "C:\Users\AndresArciniegas\AppData\Roaming\Python\Python36\site-packages\rasa_core\actions\action.py", line 348, in run
    raise Exception("Failed to execute custom action.")
Exception: Failed to execute custom action.
Action 'action_joke' ended with events '[]'
Current tracker state [{'intent_joke': 1.0, 'prev_action_listen': 1.0}, {'prev_action_joke': 1.0, 'intent_joke': 1.0}]
There is a memorised next action '0'
Predicted next action using policy_0_MemoizationPolicy
Predicted next action 'action_listen' with prob 1.00.
Action 'action_listen' ended with events '[]'
Rasa process starting
Added 'nlp_spacy' to component cache. Key 'nlp_spacy-en'.
C:\Users\AndresArciniegas\AppData\Roaming\Python\Python36\site-packages\rasa_nlu\extractors\entity_synonyms.py:85: UserWarning: Failed to load synonyms file from 'models/nlu/default/nursenlu\entity_synonyms.json'
  "".format(entity_synonyms_file))

D:\ProgramFiles\Anaconda3\envs\envbot\lib\site-packages\pykwalify\core.py:99: UnsafeLoaderWarning: 
The default 'Loader' for 'load(stream)' without further arguments can be unsafe.
Use 'load(stream, Loader=ruamel.yaml.Loader)' explicitly if that is OK.
Alternatively include the following in your code:

  import warnings
  warnings.simplefilter('ignore', ruamel.yaml.error.UnsafeLoaderWarning)

In most other cases you should consider using 'safe_load(stream)'
  data = yaml.load(stream)

Rasa process starting
Added 'nlp_spacy' to component cache. Key 'nlp_spacy-en'.
C:\Users\AndresArciniegas\AppData\Roaming\Python\Python36\site-packages\rasa_nlu\extractors\entity_synonyms.py:85: UserWarning: Failed to load synonyms file from 'models/nlu/default/nursenlu\entity_synonyms.json'
  "".format(entity_synonyms_file))

D:\ProgramFiles\Anaconda3\envs\envbot\lib\site-packages\pykwalify\core.py:99: UnsafeLoaderWarning: 
The default 'Loader' for 'load(stream)' without further arguments can be unsafe.
Use 'load(stream, Loader=ruamel.yaml.Loader)' explicitly if that is OK.
Alternatively include the following in your code:

  import warnings
  warnings.simplefilter('ignore', ruamel.yaml.error.UnsafeLoaderWarning)

In most other cases you should consider using 'safe_load(stream)'
  data = yaml.load(stream)

Rasa process starting
Added 'nlp_spacy' to component cache. Key 'nlp_spacy-en'.
C:\Users\AndresArciniegas\AppData\Roaming\Python\Python36\site-packages\rasa_nlu\extractors\entity_synonyms.py:85: UserWarning: Failed to load synonyms file from 'models/nlu/default/nursenlu\entity_synonyms.json'
  "".format(entity_synonyms_file))

D:\ProgramFiles\Anaconda3\envs\envbot\lib\site-packages\pykwalify\core.py:99: UnsafeLoaderWarning: 
The default 'Loader' for 'load(stream)' without further arguments can be unsafe.
Use 'load(stream, Loader=ruamel.yaml.Loader)' explicitly if that is OK.
Alternatively include the following in your code:

  import warnings
  warnings.simplefilter('ignore', ruamel.yaml.error.UnsafeLoaderWarning)

In most other cases you should consider using 'safe_load(stream)'
  data = yaml.load(stream)

Available web server routes: 
static                                             OPTIONS, GET, HEAD             /static/[filename]
custom_webhook_CmdlineInput.health                 OPTIONS, GET, HEAD             /webhooks/rest/
custom_webhook_CmdlineInput.receive                OPTIONS, POST                  /webhooks/rest/webhook
Rasa Core server is up and running on http://localhost:5005
Creating a new tracker for id 'default'.
C:\Users\AndresArciniegas\AppData\Roaming\Python\Python36\site-packages\sklearn\preprocessing\label.py:151: DeprecationWarning: The truth value of an empty array is ambiguous. Returning False, but in future this will result in an error. Use `array.size > 0` to check that an array is not empty.
  if diff:

Received user message 'Hi' with intent '{'name': 'greet', 'confidence': 0.67162726472034}' and entities '[]'
Logged UserUtterance - tracker now has 2 events
Current slot values: 
	location: None
	object: None
Current tracker state [{}, {'intent_greet': 1.0, 'prev_action_listen': 1.0}]
There is a memorised next action '5'
Predicted next action using policy_0_MemoizationPolicy
Predicted next action 'utter_greet' with prob 1.00.
Action 'utter_greet' ended with events '[]'
Bot utterance 'BotUttered(text: Hello human! You can call me Nurse. What can I do for you?., data: {
  "elements": null,
  "buttons": null,
  "attachment": null
})'
Current tracker state [{'intent_greet': 1.0, 'prev_action_listen': 1.0}, {'intent_greet': 1.0, 'prev_utter_greet': 1.0}]
There is a memorised next action '0'
Predicted next action using policy_0_MemoizationPolicy
Predicted next action 'action_listen' with prob 1.00.
Action 'action_listen' ended with events '[]'
Recreating tracker for id 'default'
C:\Users\AndresArciniegas\AppData\Roaming\Python\Python36\site-packages\sklearn\preprocessing\label.py:151: DeprecationWarning: The truth value of an empty array is ambiguous. Returning False, but in future this will result in an error. Use `array.size > 0` to check that an array is not empty.
  if diff:

Received user message 'Tell me a joke' with intent '{'name': 'joke', 'confidence': 0.6094320004912319}' and entities '[]'
Logged UserUtterance - tracker now has 6 events
Current slot values: 
	location: None
	object: None
Current tracker state [{'intent_greet': 1.0, 'prev_utter_greet': 1.0}, {'intent_joke': 1.0, 'prev_action_listen': 1.0}]
There is a memorised next action '9'
Predicted next action using policy_0_MemoizationPolicy
Predicted next action 'action_joke' with prob 1.00.
Encountered an exception while running action 'action_joke'. Bot will continue, but the actions events are lost. Make sure to fix the exception in your custom code.
The model predicted the custom action 'action_joke' but you didn't configure an endpoint to run this custom action. Please take a look at the docs and set an endpoint configuration. https://rasa.com/docs/core/customactions/
Traceback (most recent call last):
  File "C:\Users\AndresArciniegas\AppData\Roaming\Python\Python36\site-packages\rasa_core\processor.py", line 351, in _run_action
    events = action.run(dispatcher, tracker, self.domain)
  File "C:\Users\AndresArciniegas\AppData\Roaming\Python\Python36\site-packages\rasa_core\actions\action.py", line 321, in run
    "".format(self.name(), DOCS_BASE_URL))
Exception: The model predicted the custom action 'action_joke' but you didn't configure an endpoint to run this custom action. Please take a look at the docs and set an endpoint configuration. https://rasa.com/docs/core/customactions/
Action 'action_joke' ended with events '[]'
Current tracker state [{'intent_joke': 1.0, 'prev_action_listen': 1.0}, {'intent_joke': 1.0, 'prev_action_joke': 1.0}]
There is a memorised next action '0'
Predicted next action using policy_0_MemoizationPolicy
Predicted next action 'action_listen' with prob 1.00.
Action 'action_listen' ended with events '[]'
Rasa process starting
Added 'nlp_spacy' to component cache. Key 'nlp_spacy-en'.
C:\Users\AndresArciniegas\AppData\Roaming\Python\Python36\site-packages\rasa_nlu\extractors\entity_synonyms.py:85: UserWarning: Failed to load synonyms file from 'models/nlu/default/nursenlu\entity_synonyms.json'
  "".format(entity_synonyms_file))

D:\ProgramFiles\Anaconda3\envs\envbot\lib\site-packages\pykwalify\core.py:99: UnsafeLoaderWarning: 
The default 'Loader' for 'load(stream)' without further arguments can be unsafe.
Use 'load(stream, Loader=ruamel.yaml.Loader)' explicitly if that is OK.
Alternatively include the following in your code:

  import warnings
  warnings.simplefilter('ignore', ruamel.yaml.error.UnsafeLoaderWarning)

In most other cases you should consider using 'safe_load(stream)'
  data = yaml.load(stream)

Available web server routes: 
static                                             GET, HEAD, OPTIONS             /static/[filename]
custom_webhook_CmdlineInput.health                 GET, HEAD, OPTIONS             /webhooks/rest/
custom_webhook_CmdlineInput.receive                POST, OPTIONS                  /webhooks/rest/webhook
Rasa Core server is up and running on http://localhost:5005
Creating a new tracker for id 'default'.
C:\Users\AndresArciniegas\AppData\Roaming\Python\Python36\site-packages\sklearn\preprocessing\label.py:151: DeprecationWarning: The truth value of an empty array is ambiguous. Returning False, but in future this will result in an error. Use `array.size > 0` to check that an array is not empty.
  if diff:

Received user message 'Hi' with intent '{'name': 'greet', 'confidence': 0.67162726472034}' and entities '[]'
Logged UserUtterance - tracker now has 2 events
Current slot values: 
	location: None
	object: None
Current tracker state [{}, {'prev_action_listen': 1.0, 'intent_greet': 1.0}]
There is a memorised next action '5'
Predicted next action using policy_0_MemoizationPolicy
Predicted next action 'utter_greet' with prob 1.00.
Action 'utter_greet' ended with events '[]'
Bot utterance 'BotUttered(text: Hello! You can call me Nurse. How can I help you?, data: {
  "elements": null,
  "buttons": null,
  "attachment": null
})'
Current tracker state [{'prev_action_listen': 1.0, 'intent_greet': 1.0}, {'prev_utter_greet': 1.0, 'intent_greet': 1.0}]
There is a memorised next action '0'
Predicted next action using policy_0_MemoizationPolicy
Predicted next action 'action_listen' with prob 1.00.
Action 'action_listen' ended with events '[]'
Recreating tracker for id 'default'
C:\Users\AndresArciniegas\AppData\Roaming\Python\Python36\site-packages\sklearn\preprocessing\label.py:151: DeprecationWarning: The truth value of an empty array is ambiguous. Returning False, but in future this will result in an error. Use `array.size > 0` to check that an array is not empty.
  if diff:

Received user message 'Tell me a joke' with intent '{'name': 'joke', 'confidence': 0.6094320004912319}' and entities '[]'
Logged UserUtterance - tracker now has 6 events
Current slot values: 
	location: None
	object: None
Current tracker state [{'prev_utter_greet': 1.0, 'intent_greet': 1.0}, {'intent_joke': 1.0, 'prev_action_listen': 1.0}]
There is a memorised next action '9'
Predicted next action using policy_0_MemoizationPolicy
Predicted next action 'action_joke' with prob 1.00.
Calling action endpoint to run action 'action_joke'.
Failed to run custom action 'action_joke'. Couldn't connect to the server at 'http://localhost:5055/webhook'. Is the server running? Error: HTTPConnectionPool(host='localhost', port=5055): Max retries exceeded with url: /webhook (Caused by NewConnectionError('<urllib3.connection.HTTPConnection object at 0x000001F84588BB00>: Failed to establish a new connection: [WinError 10061] No connection could be made because the target machine actively refused it',))
Encountered an exception while running action 'action_joke'. Bot will continue, but the actions events are lost. Make sure to fix the exception in your custom code.
Failed to execute custom action.
Traceback (most recent call last):
  File "D:\ProgramFiles\Anaconda3\envs\envbot\lib\site-packages\urllib3\connection.py", line 171, in _new_conn
    (self._dns_host, self.port), self.timeout, **extra_kw)
  File "D:\ProgramFiles\Anaconda3\envs\envbot\lib\site-packages\urllib3\util\connection.py", line 79, in create_connection
    raise err
  File "D:\ProgramFiles\Anaconda3\envs\envbot\lib\site-packages\urllib3\util\connection.py", line 69, in create_connection
    sock.connect(sa)
ConnectionRefusedError: [WinError 10061] No connection could be made because the target machine actively refused it

During handling of the above exception, another exception occurred:

Traceback (most recent call last):
  File "D:\ProgramFiles\Anaconda3\envs\envbot\lib\site-packages\urllib3\connectionpool.py", line 600, in urlopen
    chunked=chunked)
  File "D:\ProgramFiles\Anaconda3\envs\envbot\lib\site-packages\urllib3\connectionpool.py", line 354, in _make_request
    conn.request(method, url, **httplib_request_kw)
  File "D:\ProgramFiles\Anaconda3\envs\envbot\lib\http\client.py", line 1239, in request
    self._send_request(method, url, body, headers, encode_chunked)
  File "D:\ProgramFiles\Anaconda3\envs\envbot\lib\http\client.py", line 1285, in _send_request
    self.endheaders(body, encode_chunked=encode_chunked)
  File "D:\ProgramFiles\Anaconda3\envs\envbot\lib\http\client.py", line 1234, in endheaders
    self._send_output(message_body, encode_chunked=encode_chunked)
  File "D:\ProgramFiles\Anaconda3\envs\envbot\lib\http\client.py", line 1026, in _send_output
    self.send(msg)
  File "D:\ProgramFiles\Anaconda3\envs\envbot\lib\http\client.py", line 964, in send
    self.connect()
  File "D:\ProgramFiles\Anaconda3\envs\envbot\lib\site-packages\urllib3\connection.py", line 196, in connect
    conn = self._new_conn()
  File "D:\ProgramFiles\Anaconda3\envs\envbot\lib\site-packages\urllib3\connection.py", line 180, in _new_conn
    self, "Failed to establish a new connection: %s" % e)
urllib3.exceptions.NewConnectionError: <urllib3.connection.HTTPConnection object at 0x000001F84588BB00>: Failed to establish a new connection: [WinError 10061] No connection could be made because the target machine actively refused it

During handling of the above exception, another exception occurred:

Traceback (most recent call last):
  File "D:\ProgramFiles\Anaconda3\envs\envbot\lib\site-packages\requests\adapters.py", line 449, in send
    timeout=timeout
  File "D:\ProgramFiles\Anaconda3\envs\envbot\lib\site-packages\urllib3\connectionpool.py", line 638, in urlopen
    _stacktrace=sys.exc_info()[2])
  File "D:\ProgramFiles\Anaconda3\envs\envbot\lib\site-packages\urllib3\util\retry.py", line 398, in increment
    raise MaxRetryError(_pool, url, error or ResponseError(cause))
urllib3.exceptions.MaxRetryError: HTTPConnectionPool(host='localhost', port=5055): Max retries exceeded with url: /webhook (Caused by NewConnectionError('<urllib3.connection.HTTPConnection object at 0x000001F84588BB00>: Failed to establish a new connection: [WinError 10061] No connection could be made because the target machine actively refused it',))

During handling of the above exception, another exception occurred:

Traceback (most recent call last):
  File "C:\Users\AndresArciniegas\AppData\Roaming\Python\Python36\site-packages\rasa_core\actions\action.py", line 327, in run
    json=json, method="post", timeout=DEFAULT_REQUEST_TIMEOUT)
  File "C:\Users\AndresArciniegas\AppData\Roaming\Python\Python36\site-packages\rasa_core\utils.py", line 748, in request
    **kwargs)
  File "D:\ProgramFiles\Anaconda3\envs\envbot\lib\site-packages\requests\api.py", line 60, in request
    return session.request(method=method, url=url, **kwargs)
  File "D:\ProgramFiles\Anaconda3\envs\envbot\lib\site-packages\requests\sessions.py", line 524, in request
    resp = self.send(prep, **send_kwargs)
  File "D:\ProgramFiles\Anaconda3\envs\envbot\lib\site-packages\requests\sessions.py", line 637, in send
    r = adapter.send(request, **kwargs)
  File "D:\ProgramFiles\Anaconda3\envs\envbot\lib\site-packages\requests\adapters.py", line 516, in send
    raise ConnectionError(e, request=request)
requests.exceptions.ConnectionError: HTTPConnectionPool(host='localhost', port=5055): Max retries exceeded with url: /webhook (Caused by NewConnectionError('<urllib3.connection.HTTPConnection object at 0x000001F84588BB00>: Failed to establish a new connection: [WinError 10061] No connection could be made because the target machine actively refused it',))

During handling of the above exception, another exception occurred:

Traceback (most recent call last):
  File "C:\Users\AndresArciniegas\AppData\Roaming\Python\Python36\site-packages\rasa_core\processor.py", line 351, in _run_action
    events = action.run(dispatcher, tracker, self.domain)
  File "C:\Users\AndresArciniegas\AppData\Roaming\Python\Python36\site-packages\rasa_core\actions\action.py", line 348, in run
    raise Exception("Failed to execute custom action.")
Exception: Failed to execute custom action.
Action 'action_joke' ended with events '[]'
Current tracker state [{'intent_joke': 1.0, 'prev_action_listen': 1.0}, {'prev_action_joke': 1.0, 'intent_joke': 1.0}]
There is a memorised next action '0'
Predicted next action using policy_0_MemoizationPolicy
Predicted next action 'action_listen' with prob 1.00.
Action 'action_listen' ended with events '[]'
Rasa process starting
Rasa process starting
Added 'nlp_spacy' to component cache. Key 'nlp_spacy-en'.
C:\Users\AndresArciniegas\AppData\Roaming\Python\Python36\site-packages\rasa_nlu\extractors\entity_synonyms.py:85: UserWarning: Failed to load synonyms file from 'models/nlu/default/nursenlu\entity_synonyms.json'
  "".format(entity_synonyms_file))

D:\ProgramFiles\Anaconda3\envs\envbot\lib\site-packages\pykwalify\core.py:99: UnsafeLoaderWarning: 
The default 'Loader' for 'load(stream)' without further arguments can be unsafe.
Use 'load(stream, Loader=ruamel.yaml.Loader)' explicitly if that is OK.
Alternatively include the following in your code:

  import warnings
  warnings.simplefilter('ignore', ruamel.yaml.error.UnsafeLoaderWarning)

In most other cases you should consider using 'safe_load(stream)'
  data = yaml.load(stream)

Available web server routes: 
static                                             HEAD, GET, OPTIONS             /static/[filename]
custom_webhook_CmdlineInput.health                 HEAD, GET, OPTIONS             /webhooks/rest/
custom_webhook_CmdlineInput.receive                POST, OPTIONS                  /webhooks/rest/webhook
Rasa Core server is up and running on http://localhost:5005
Rasa process starting
Added 'nlp_spacy' to component cache. Key 'nlp_spacy-en'.
C:\Users\AndresArciniegas\AppData\Roaming\Python\Python36\site-packages\rasa_nlu\extractors\entity_synonyms.py:85: UserWarning: Failed to load synonyms file from 'models/nlu/default/nursenlu\entity_synonyms.json'
  "".format(entity_synonyms_file))

D:\ProgramFiles\Anaconda3\envs\envbot\lib\site-packages\pykwalify\core.py:99: UnsafeLoaderWarning: 
The default 'Loader' for 'load(stream)' without further arguments can be unsafe.
Use 'load(stream, Loader=ruamel.yaml.Loader)' explicitly if that is OK.
Alternatively include the following in your code:

  import warnings
  warnings.simplefilter('ignore', ruamel.yaml.error.UnsafeLoaderWarning)

In most other cases you should consider using 'safe_load(stream)'
  data = yaml.load(stream)

Available web server routes: 
static                                             HEAD, OPTIONS, GET             /static/[filename]
custom_webhook_CmdlineInput.health                 HEAD, OPTIONS, GET             /webhooks/rest/
custom_webhook_CmdlineInput.receive                OPTIONS, POST                  /webhooks/rest/webhook
Rasa Core server is up and running on http://localhost:5005
Rasa process starting
Added 'nlp_spacy' to component cache. Key 'nlp_spacy-en'.
C:\Users\AndresArciniegas\AppData\Roaming\Python\Python36\site-packages\rasa_nlu\extractors\entity_synonyms.py:85: UserWarning: Failed to load synonyms file from 'models/nlu/default/nursenlu\entity_synonyms.json'
  "".format(entity_synonyms_file))

D:\ProgramFiles\Anaconda3\envs\envbot\lib\site-packages\pykwalify\core.py:99: UnsafeLoaderWarning: 
The default 'Loader' for 'load(stream)' without further arguments can be unsafe.
Use 'load(stream, Loader=ruamel.yaml.Loader)' explicitly if that is OK.
Alternatively include the following in your code:

  import warnings
  warnings.simplefilter('ignore', ruamel.yaml.error.UnsafeLoaderWarning)

In most other cases you should consider using 'safe_load(stream)'
  data = yaml.load(stream)

Available web server routes: 
static                                             GET, HEAD, OPTIONS             /static/[filename]
custom_webhook_CmdlineInput.health                 GET, HEAD, OPTIONS             /webhooks/rest/
custom_webhook_CmdlineInput.receive                POST, OPTIONS                  /webhooks/rest/webhook
Rasa Core server is up and running on http://localhost:5005
Rasa process starting
Added 'nlp_spacy' to component cache. Key 'nlp_spacy-en'.
C:\Users\AndresArciniegas\AppData\Roaming\Python\Python36\site-packages\rasa_nlu\extractors\entity_synonyms.py:85: UserWarning: Failed to load synonyms file from 'models/nlu/default/nursenlu\entity_synonyms.json'
  "".format(entity_synonyms_file))

D:\ProgramFiles\Anaconda3\envs\envbot\lib\site-packages\pykwalify\core.py:99: UnsafeLoaderWarning: 
The default 'Loader' for 'load(stream)' without further arguments can be unsafe.
Use 'load(stream, Loader=ruamel.yaml.Loader)' explicitly if that is OK.
Alternatively include the following in your code:

  import warnings
  warnings.simplefilter('ignore', ruamel.yaml.error.UnsafeLoaderWarning)

In most other cases you should consider using 'safe_load(stream)'
  data = yaml.load(stream)

Available web server routes: 
static                                             GET, OPTIONS, HEAD             /static/[filename]
custom_webhook_CmdlineInput.health                 GET, OPTIONS, HEAD             /webhooks/rest/
custom_webhook_CmdlineInput.receive                OPTIONS, POST                  /webhooks/rest/webhook
Rasa Core server is up and running on http://localhost:5005
Rasa process starting
Added 'nlp_spacy' to component cache. Key 'nlp_spacy-en'.
C:\Users\AndresArciniegas\AppData\Roaming\Python\Python36\site-packages\rasa_nlu\extractors\entity_synonyms.py:85: UserWarning: Failed to load synonyms file from 'models/nlu/default/nursenlu\entity_synonyms.json'
  "".format(entity_synonyms_file))

D:\ProgramFiles\Anaconda3\envs\envbot\lib\site-packages\pykwalify\core.py:99: UnsafeLoaderWarning: 
The default 'Loader' for 'load(stream)' without further arguments can be unsafe.
Use 'load(stream, Loader=ruamel.yaml.Loader)' explicitly if that is OK.
Alternatively include the following in your code:

  import warnings
  warnings.simplefilter('ignore', ruamel.yaml.error.UnsafeLoaderWarning)

In most other cases you should consider using 'safe_load(stream)'
  data = yaml.load(stream)

Available web server routes: 
static                                             HEAD, OPTIONS, GET             /static/[filename]
custom_webhook_CmdlineInput.health                 HEAD, OPTIONS, GET             /webhooks/rest/
custom_webhook_CmdlineInput.receive                OPTIONS, POST                  /webhooks/rest/webhook
Rasa Core server is up and running on http://localhost:5005
Rasa process starting
Added 'nlp_spacy' to component cache. Key 'nlp_spacy-en'.
C:\Users\AndresArciniegas\AppData\Roaming\Python\Python36\site-packages\rasa_nlu\extractors\entity_synonyms.py:85: UserWarning: Failed to load synonyms file from 'models/nlu/default/nursenlu\entity_synonyms.json'
  "".format(entity_synonyms_file))

D:\ProgramFiles\Anaconda3\envs\envbot\lib\site-packages\pykwalify\core.py:99: UnsafeLoaderWarning: 
The default 'Loader' for 'load(stream)' without further arguments can be unsafe.
Use 'load(stream, Loader=ruamel.yaml.Loader)' explicitly if that is OK.
Alternatively include the following in your code:

  import warnings
  warnings.simplefilter('ignore', ruamel.yaml.error.UnsafeLoaderWarning)

In most other cases you should consider using 'safe_load(stream)'
  data = yaml.load(stream)

Available web server routes: 
static                                             HEAD, GET, OPTIONS             /static/[filename]
custom_webhook_CmdlineInput.health                 HEAD, GET, OPTIONS             /webhooks/rest/
custom_webhook_CmdlineInput.receive                POST, OPTIONS                  /webhooks/rest/webhook
Rasa Core server is up and running on http://localhost:5005
Rasa process starting
Added 'nlp_spacy' to component cache. Key 'nlp_spacy-en'.
C:\Users\AndresArciniegas\AppData\Roaming\Python\Python36\site-packages\rasa_nlu\extractors\entity_synonyms.py:85: UserWarning: Failed to load synonyms file from 'models/nlu/default/nursenlu\entity_synonyms.json'
  "".format(entity_synonyms_file))

D:\ProgramFiles\Anaconda3\envs\envbot\lib\site-packages\pykwalify\core.py:99: UnsafeLoaderWarning: 
The default 'Loader' for 'load(stream)' without further arguments can be unsafe.
Use 'load(stream, Loader=ruamel.yaml.Loader)' explicitly if that is OK.
Alternatively include the following in your code:

  import warnings
  warnings.simplefilter('ignore', ruamel.yaml.error.UnsafeLoaderWarning)

In most other cases you should consider using 'safe_load(stream)'
  data = yaml.load(stream)

Available web server routes: 
static                                             OPTIONS, GET, HEAD             /static/[filename]
custom_webhook_CmdlineInput.health                 OPTIONS, GET, HEAD             /webhooks/rest/
custom_webhook_CmdlineInput.receive                OPTIONS, POST                  /webhooks/rest/webhook
Rasa Core server is up and running on http://localhost:5005
Creating a new tracker for id 'default'.
C:\Users\AndresArciniegas\AppData\Roaming\Python\Python36\site-packages\sklearn\preprocessing\label.py:151: DeprecationWarning: The truth value of an empty array is ambiguous. Returning False, but in future this will result in an error. Use `array.size > 0` to check that an array is not empty.
  if diff:

Received user message 'Hello' with intent '{'name': 'greet', 'confidence': 0.6280013948232969}' and entities '[]'
Logged UserUtterance - tracker now has 2 events
Current slot values: 
	location: None
	object: None
Current tracker state [{}, {'intent_greet': 1.0, 'prev_action_listen': 1.0}]
There is a memorised next action '5'
Predicted next action using policy_0_MemoizationPolicy
Predicted next action 'utter_greet' with prob 1.00.
Action 'utter_greet' ended with events '[]'
Bot utterance 'BotUttered(text: Greetings. You can call me Nurse. How may I help you?, data: {
  "elements": null,
  "buttons": null,
  "attachment": null
})'
Current tracker state [{'intent_greet': 1.0, 'prev_action_listen': 1.0}, {'intent_greet': 1.0, 'prev_utter_greet': 1.0}]
There is a memorised next action '0'
Predicted next action using policy_0_MemoizationPolicy
Predicted next action 'action_listen' with prob 1.00.
Action 'action_listen' ended with events '[]'
Recreating tracker for id 'default'
C:\Users\AndresArciniegas\AppData\Roaming\Python\Python36\site-packages\sklearn\preprocessing\label.py:151: DeprecationWarning: The truth value of an empty array is ambiguous. Returning False, but in future this will result in an error. Use `array.size > 0` to check that an array is not empty.
  if diff:

Received user message 'Tell me a joke' with intent '{'name': 'joke', 'confidence': 0.6094320004912319}' and entities '[]'
Logged UserUtterance - tracker now has 6 events
Current slot values: 
	location: None
	object: None
Current tracker state [{'intent_greet': 1.0, 'prev_utter_greet': 1.0}, {'prev_action_listen': 1.0, 'intent_joke': 1.0}]
There is a memorised next action '9'
Predicted next action using policy_0_MemoizationPolicy
Predicted next action 'action_joke' with prob 1.00.
Calling action endpoint to run action 'action_joke'.
Failed to run custom action 'action_joke'. Couldn't connect to the server at 'http://localhost:5055/webhook'. Is the server running? Error: HTTPConnectionPool(host='localhost', port=5055): Max retries exceeded with url: /webhook (Caused by NewConnectionError('<urllib3.connection.HTTPConnection object at 0x0000025603556B00>: Failed to establish a new connection: [WinError 10061] No connection could be made because the target machine actively refused it',))
Encountered an exception while running action 'action_joke'. Bot will continue, but the actions events are lost. Make sure to fix the exception in your custom code.
Failed to execute custom action.
Traceback (most recent call last):
  File "D:\ProgramFiles\Anaconda3\envs\envbot\lib\site-packages\urllib3\connection.py", line 171, in _new_conn
    (self._dns_host, self.port), self.timeout, **extra_kw)
  File "D:\ProgramFiles\Anaconda3\envs\envbot\lib\site-packages\urllib3\util\connection.py", line 79, in create_connection
    raise err
  File "D:\ProgramFiles\Anaconda3\envs\envbot\lib\site-packages\urllib3\util\connection.py", line 69, in create_connection
    sock.connect(sa)
ConnectionRefusedError: [WinError 10061] No connection could be made because the target machine actively refused it

During handling of the above exception, another exception occurred:

Traceback (most recent call last):
  File "D:\ProgramFiles\Anaconda3\envs\envbot\lib\site-packages\urllib3\connectionpool.py", line 600, in urlopen
    chunked=chunked)
  File "D:\ProgramFiles\Anaconda3\envs\envbot\lib\site-packages\urllib3\connectionpool.py", line 354, in _make_request
    conn.request(method, url, **httplib_request_kw)
  File "D:\ProgramFiles\Anaconda3\envs\envbot\lib\http\client.py", line 1239, in request
    self._send_request(method, url, body, headers, encode_chunked)
  File "D:\ProgramFiles\Anaconda3\envs\envbot\lib\http\client.py", line 1285, in _send_request
    self.endheaders(body, encode_chunked=encode_chunked)
  File "D:\ProgramFiles\Anaconda3\envs\envbot\lib\http\client.py", line 1234, in endheaders
    self._send_output(message_body, encode_chunked=encode_chunked)
  File "D:\ProgramFiles\Anaconda3\envs\envbot\lib\http\client.py", line 1026, in _send_output
    self.send(msg)
  File "D:\ProgramFiles\Anaconda3\envs\envbot\lib\http\client.py", line 964, in send
    self.connect()
  File "D:\ProgramFiles\Anaconda3\envs\envbot\lib\site-packages\urllib3\connection.py", line 196, in connect
    conn = self._new_conn()
  File "D:\ProgramFiles\Anaconda3\envs\envbot\lib\site-packages\urllib3\connection.py", line 180, in _new_conn
    self, "Failed to establish a new connection: %s" % e)
urllib3.exceptions.NewConnectionError: <urllib3.connection.HTTPConnection object at 0x0000025603556B00>: Failed to establish a new connection: [WinError 10061] No connection could be made because the target machine actively refused it

During handling of the above exception, another exception occurred:

Traceback (most recent call last):
  File "D:\ProgramFiles\Anaconda3\envs\envbot\lib\site-packages\requests\adapters.py", line 449, in send
    timeout=timeout
  File "D:\ProgramFiles\Anaconda3\envs\envbot\lib\site-packages\urllib3\connectionpool.py", line 638, in urlopen
    _stacktrace=sys.exc_info()[2])
  File "D:\ProgramFiles\Anaconda3\envs\envbot\lib\site-packages\urllib3\util\retry.py", line 398, in increment
    raise MaxRetryError(_pool, url, error or ResponseError(cause))
urllib3.exceptions.MaxRetryError: HTTPConnectionPool(host='localhost', port=5055): Max retries exceeded with url: /webhook (Caused by NewConnectionError('<urllib3.connection.HTTPConnection object at 0x0000025603556B00>: Failed to establish a new connection: [WinError 10061] No connection could be made because the target machine actively refused it',))

During handling of the above exception, another exception occurred:

Traceback (most recent call last):
  File "C:\Users\AndresArciniegas\AppData\Roaming\Python\Python36\site-packages\rasa_core\actions\action.py", line 327, in run
    json=json, method="post", timeout=DEFAULT_REQUEST_TIMEOUT)
  File "C:\Users\AndresArciniegas\AppData\Roaming\Python\Python36\site-packages\rasa_core\utils.py", line 748, in request
    **kwargs)
  File "D:\ProgramFiles\Anaconda3\envs\envbot\lib\site-packages\requests\api.py", line 60, in request
    return session.request(method=method, url=url, **kwargs)
  File "D:\ProgramFiles\Anaconda3\envs\envbot\lib\site-packages\requests\sessions.py", line 524, in request
    resp = self.send(prep, **send_kwargs)
  File "D:\ProgramFiles\Anaconda3\envs\envbot\lib\site-packages\requests\sessions.py", line 637, in send
    r = adapter.send(request, **kwargs)
  File "D:\ProgramFiles\Anaconda3\envs\envbot\lib\site-packages\requests\adapters.py", line 516, in send
    raise ConnectionError(e, request=request)
requests.exceptions.ConnectionError: HTTPConnectionPool(host='localhost', port=5055): Max retries exceeded with url: /webhook (Caused by NewConnectionError('<urllib3.connection.HTTPConnection object at 0x0000025603556B00>: Failed to establish a new connection: [WinError 10061] No connection could be made because the target machine actively refused it',))

During handling of the above exception, another exception occurred:

Traceback (most recent call last):
  File "C:\Users\AndresArciniegas\AppData\Roaming\Python\Python36\site-packages\rasa_core\processor.py", line 351, in _run_action
    events = action.run(dispatcher, tracker, self.domain)
  File "C:\Users\AndresArciniegas\AppData\Roaming\Python\Python36\site-packages\rasa_core\actions\action.py", line 348, in run
    raise Exception("Failed to execute custom action.")
Exception: Failed to execute custom action.
Action 'action_joke' ended with events '[]'
Current tracker state [{'prev_action_listen': 1.0, 'intent_joke': 1.0}, {'prev_action_joke': 1.0, 'intent_joke': 1.0}]
There is a memorised next action '0'
Predicted next action using policy_0_MemoizationPolicy
Predicted next action 'action_listen' with prob 1.00.
Action 'action_listen' ended with events '[]'
Rasa process starting
Added 'nlp_spacy' to component cache. Key 'nlp_spacy-en'.
C:\Users\AndresArciniegas\AppData\Roaming\Python\Python36\site-packages\rasa_nlu\extractors\entity_synonyms.py:85: UserWarning: Failed to load synonyms file from 'models/nlu/default/nursenlu\entity_synonyms.json'
  "".format(entity_synonyms_file))

D:\ProgramFiles\Anaconda3\envs\envbot\lib\site-packages\pykwalify\core.py:99: UnsafeLoaderWarning: 
The default 'Loader' for 'load(stream)' without further arguments can be unsafe.
Use 'load(stream, Loader=ruamel.yaml.Loader)' explicitly if that is OK.
Alternatively include the following in your code:

  import warnings
  warnings.simplefilter('ignore', ruamel.yaml.error.UnsafeLoaderWarning)

In most other cases you should consider using 'safe_load(stream)'
  data = yaml.load(stream)

Available web server routes: 
static                                             HEAD, OPTIONS, GET             /static/[filename]
custom_webhook_CmdlineInput.health                 HEAD, OPTIONS, GET             /webhooks/rest/
custom_webhook_CmdlineInput.receive                POST, OPTIONS                  /webhooks/rest/webhook
Rasa Core server is up and running on http://localhost:5005
Creating a new tracker for id 'default'.
C:\Users\AndresArciniegas\AppData\Roaming\Python\Python36\site-packages\sklearn\preprocessing\label.py:151: DeprecationWarning: The truth value of an empty array is ambiguous. Returning False, but in future this will result in an error. Use `array.size > 0` to check that an array is not empty.
  if diff:

Received user message 'Hola' with intent '{'name': 'goodbye', 'confidence': 0.5534913007880118}' and entities '[]'
Logged UserUtterance - tracker now has 2 events
Current slot values: 
	location: None
	object: None
Current tracker state [{}, {'prev_action_listen': 1.0, 'intent_goodbye': 1.0}]
There is a memorised next action '7'
Predicted next action using policy_0_MemoizationPolicy
Predicted next action 'utter_standby' with prob 1.00.
Action 'utter_standby' ended with events '[]'
Bot utterance 'BotUttered(text: I'm at your service., data: {
  "elements": null,
  "buttons": null,
  "attachment": null
})'
Current tracker state [{'prev_action_listen': 1.0, 'intent_goodbye': 1.0}, {'intent_goodbye': 1.0, 'prev_utter_standby': 1.0}]
There is a memorised next action '0'
Predicted next action using policy_0_MemoizationPolicy
Predicted next action 'action_listen' with prob 1.00.
Action 'action_listen' ended with events '[]'
Recreating tracker for id 'default'
C:\Users\AndresArciniegas\AppData\Roaming\Python\Python36\site-packages\sklearn\preprocessing\label.py:151: DeprecationWarning: The truth value of an empty array is ambiguous. Returning False, but in future this will result in an error. Use `array.size > 0` to check that an array is not empty.
  if diff:

Received user message 'Hello' with intent '{'name': 'greet', 'confidence': 0.6280013948232969}' and entities '[]'
Logged UserUtterance - tracker now has 6 events
Current slot values: 
	location: None
	object: None
Current tracker state [{'intent_goodbye': 1.0, 'prev_utter_standby': 1.0}, {'prev_action_listen': 1.0, 'intent_greet': 1.0}]
There is a memorised next action '5'
Predicted next action using policy_0_MemoizationPolicy
Predicted next action 'utter_greet' with prob 1.00.
Action 'utter_greet' ended with events '[]'
Bot utterance 'BotUttered(text: Greetings. You can call me Nurse. How may I help you?, data: {
  "elements": null,
  "buttons": null,
  "attachment": null
})'
Current tracker state [{'prev_action_listen': 1.0, 'intent_greet': 1.0}, {'intent_greet': 1.0, 'prev_utter_greet': 1.0}]
There is a memorised next action '0'
Predicted next action using policy_0_MemoizationPolicy
Predicted next action 'action_listen' with prob 1.00.
Action 'action_listen' ended with events '[]'
Recreating tracker for id 'default'
C:\Users\AndresArciniegas\AppData\Roaming\Python\Python36\site-packages\sklearn\preprocessing\label.py:151: DeprecationWarning: The truth value of an empty array is ambiguous. Returning False, but in future this will result in an error. Use `array.size > 0` to check that an array is not empty.
  if diff:

Received user message 'Tell me a joke' with intent '{'name': 'joke', 'confidence': 0.6094320004912319}' and entities '[]'
Logged UserUtterance - tracker now has 10 events
Current slot values: 
	location: None
	object: None
Current tracker state [{'intent_greet': 1.0, 'prev_utter_greet': 1.0}, {'prev_action_listen': 1.0, 'intent_joke': 1.0}]
There is a memorised next action '9'
Predicted next action using policy_0_MemoizationPolicy
Predicted next action 'action_joke' with prob 1.00.
Calling action endpoint to run action 'action_joke'.
Failed to run custom action 'action_joke'. Couldn't connect to the server at 'http://localhost:5055/webhook'. Is the server running? Error: HTTPConnectionPool(host='localhost', port=5055): Max retries exceeded with url: /webhook (Caused by NewConnectionError('<urllib3.connection.HTTPConnection object at 0x000001AF87BF1DD8>: Failed to establish a new connection: [WinError 10061] No connection could be made because the target machine actively refused it',))
Encountered an exception while running action 'action_joke'. Bot will continue, but the actions events are lost. Make sure to fix the exception in your custom code.
Failed to execute custom action.
Traceback (most recent call last):
  File "D:\ProgramFiles\Anaconda3\envs\envbot\lib\site-packages\urllib3\connection.py", line 171, in _new_conn
    (self._dns_host, self.port), self.timeout, **extra_kw)
  File "D:\ProgramFiles\Anaconda3\envs\envbot\lib\site-packages\urllib3\util\connection.py", line 79, in create_connection
    raise err
  File "D:\ProgramFiles\Anaconda3\envs\envbot\lib\site-packages\urllib3\util\connection.py", line 69, in create_connection
    sock.connect(sa)
ConnectionRefusedError: [WinError 10061] No connection could be made because the target machine actively refused it

During handling of the above exception, another exception occurred:

Traceback (most recent call last):
  File "D:\ProgramFiles\Anaconda3\envs\envbot\lib\site-packages\urllib3\connectionpool.py", line 600, in urlopen
    chunked=chunked)
  File "D:\ProgramFiles\Anaconda3\envs\envbot\lib\site-packages\urllib3\connectionpool.py", line 354, in _make_request
    conn.request(method, url, **httplib_request_kw)
  File "D:\ProgramFiles\Anaconda3\envs\envbot\lib\http\client.py", line 1239, in request
    self._send_request(method, url, body, headers, encode_chunked)
  File "D:\ProgramFiles\Anaconda3\envs\envbot\lib\http\client.py", line 1285, in _send_request
    self.endheaders(body, encode_chunked=encode_chunked)
  File "D:\ProgramFiles\Anaconda3\envs\envbot\lib\http\client.py", line 1234, in endheaders
    self._send_output(message_body, encode_chunked=encode_chunked)
  File "D:\ProgramFiles\Anaconda3\envs\envbot\lib\http\client.py", line 1026, in _send_output
    self.send(msg)
  File "D:\ProgramFiles\Anaconda3\envs\envbot\lib\http\client.py", line 964, in send
    self.connect()
  File "D:\ProgramFiles\Anaconda3\envs\envbot\lib\site-packages\urllib3\connection.py", line 196, in connect
    conn = self._new_conn()
  File "D:\ProgramFiles\Anaconda3\envs\envbot\lib\site-packages\urllib3\connection.py", line 180, in _new_conn
    self, "Failed to establish a new connection: %s" % e)
urllib3.exceptions.NewConnectionError: <urllib3.connection.HTTPConnection object at 0x000001AF87BF1DD8>: Failed to establish a new connection: [WinError 10061] No connection could be made because the target machine actively refused it

During handling of the above exception, another exception occurred:

Traceback (most recent call last):
  File "D:\ProgramFiles\Anaconda3\envs\envbot\lib\site-packages\requests\adapters.py", line 449, in send
    timeout=timeout
  File "D:\ProgramFiles\Anaconda3\envs\envbot\lib\site-packages\urllib3\connectionpool.py", line 638, in urlopen
    _stacktrace=sys.exc_info()[2])
  File "D:\ProgramFiles\Anaconda3\envs\envbot\lib\site-packages\urllib3\util\retry.py", line 398, in increment
    raise MaxRetryError(_pool, url, error or ResponseError(cause))
urllib3.exceptions.MaxRetryError: HTTPConnectionPool(host='localhost', port=5055): Max retries exceeded with url: /webhook (Caused by NewConnectionError('<urllib3.connection.HTTPConnection object at 0x000001AF87BF1DD8>: Failed to establish a new connection: [WinError 10061] No connection could be made because the target machine actively refused it',))

During handling of the above exception, another exception occurred:

Traceback (most recent call last):
  File "C:\Users\AndresArciniegas\AppData\Roaming\Python\Python36\site-packages\rasa_core\actions\action.py", line 327, in run
    json=json, method="post", timeout=DEFAULT_REQUEST_TIMEOUT)
  File "C:\Users\AndresArciniegas\AppData\Roaming\Python\Python36\site-packages\rasa_core\utils.py", line 748, in request
    **kwargs)
  File "D:\ProgramFiles\Anaconda3\envs\envbot\lib\site-packages\requests\api.py", line 60, in request
    return session.request(method=method, url=url, **kwargs)
  File "D:\ProgramFiles\Anaconda3\envs\envbot\lib\site-packages\requests\sessions.py", line 524, in request
    resp = self.send(prep, **send_kwargs)
  File "D:\ProgramFiles\Anaconda3\envs\envbot\lib\site-packages\requests\sessions.py", line 637, in send
    r = adapter.send(request, **kwargs)
  File "D:\ProgramFiles\Anaconda3\envs\envbot\lib\site-packages\requests\adapters.py", line 516, in send
    raise ConnectionError(e, request=request)
requests.exceptions.ConnectionError: HTTPConnectionPool(host='localhost', port=5055): Max retries exceeded with url: /webhook (Caused by NewConnectionError('<urllib3.connection.HTTPConnection object at 0x000001AF87BF1DD8>: Failed to establish a new connection: [WinError 10061] No connection could be made because the target machine actively refused it',))

During handling of the above exception, another exception occurred:

Traceback (most recent call last):
  File "C:\Users\AndresArciniegas\AppData\Roaming\Python\Python36\site-packages\rasa_core\processor.py", line 351, in _run_action
    events = action.run(dispatcher, tracker, self.domain)
  File "C:\Users\AndresArciniegas\AppData\Roaming\Python\Python36\site-packages\rasa_core\actions\action.py", line 348, in run
    raise Exception("Failed to execute custom action.")
Exception: Failed to execute custom action.
Action 'action_joke' ended with events '[]'
Current tracker state [{'prev_action_listen': 1.0, 'intent_joke': 1.0}, {'prev_action_joke': 1.0, 'intent_joke': 1.0}]
There is a memorised next action '0'
Predicted next action using policy_0_MemoizationPolicy
Predicted next action 'action_listen' with prob 1.00.
Action 'action_listen' ended with events '[]'
Rasa process starting
Added 'nlp_spacy' to component cache. Key 'nlp_spacy-en'.
C:\Users\AndresArciniegas\AppData\Roaming\Python\Python36\site-packages\rasa_nlu\extractors\entity_synonyms.py:85: UserWarning: Failed to load synonyms file from 'models/nlu/default/nursenlu\entity_synonyms.json'
  "".format(entity_synonyms_file))

D:\ProgramFiles\Anaconda3\envs\envbot\lib\site-packages\pykwalify\core.py:99: UnsafeLoaderWarning: 
The default 'Loader' for 'load(stream)' without further arguments can be unsafe.
Use 'load(stream, Loader=ruamel.yaml.Loader)' explicitly if that is OK.
Alternatively include the following in your code:

  import warnings
  warnings.simplefilter('ignore', ruamel.yaml.error.UnsafeLoaderWarning)

In most other cases you should consider using 'safe_load(stream)'
  data = yaml.load(stream)

Available web server routes: 
static                                             OPTIONS, GET, HEAD             /static/[filename]
custom_webhook_CmdlineInput.health                 OPTIONS, GET, HEAD             /webhooks/rest/
custom_webhook_CmdlineInput.receive                OPTIONS, POST                  /webhooks/rest/webhook
Rasa Core server is up and running on http://localhost:5005
Creating a new tracker for id 'default'.
C:\Users\AndresArciniegas\AppData\Roaming\Python\Python36\site-packages\sklearn\preprocessing\label.py:151: DeprecationWarning: The truth value of an empty array is ambiguous. Returning False, but in future this will result in an error. Use `array.size > 0` to check that an array is not empty.
  if diff:

Received user message 'Hello' with intent '{'name': 'greet', 'confidence': 0.6280013948232969}' and entities '[]'
Logged UserUtterance - tracker now has 2 events
Current slot values: 
	location: None
	object: None
Current tracker state [{}, {'intent_greet': 1.0, 'prev_action_listen': 1.0}]
There is a memorised next action '5'
Predicted next action using policy_0_MemoizationPolicy
Predicted next action 'utter_greet' with prob 1.00.
Action 'utter_greet' ended with events '[]'
Bot utterance 'BotUttered(text: Hello human! You can call me Nurse. What can I do for you?., data: {
  "elements": null,
  "buttons": null,
  "attachment": null
})'
Current tracker state [{'intent_greet': 1.0, 'prev_action_listen': 1.0}, {'prev_utter_greet': 1.0, 'intent_greet': 1.0}]
There is a memorised next action '0'
Predicted next action using policy_0_MemoizationPolicy
Predicted next action 'action_listen' with prob 1.00.
Action 'action_listen' ended with events '[]'
Recreating tracker for id 'default'
C:\Users\AndresArciniegas\AppData\Roaming\Python\Python36\site-packages\sklearn\preprocessing\label.py:151: DeprecationWarning: The truth value of an empty array is ambiguous. Returning False, but in future this will result in an error. Use `array.size > 0` to check that an array is not empty.
  if diff:

Received user message 'Tell me a joke' with intent '{'name': 'joke', 'confidence': 0.6094320004912319}' and entities '[]'
Logged UserUtterance - tracker now has 6 events
Current slot values: 
	location: None
	object: None
Current tracker state [{'prev_utter_greet': 1.0, 'intent_greet': 1.0}, {'prev_action_listen': 1.0, 'intent_joke': 1.0}]
There is a memorised next action '9'
Predicted next action using policy_0_MemoizationPolicy
Predicted next action 'action_joke' with prob 1.00.
Calling action endpoint to run action 'action_joke'.
Action 'action_joke' ended with events '[]'
Bot utterance 'BotUttered(text: Anthony Weiner resigned from congress and immediately committed suicide after learning that he had also accidently sent a twit to Chuck Norris., data: {
  "elements": null,
  "buttons": null,
  "attachment": null
})'
Current tracker state [{'prev_action_listen': 1.0, 'intent_joke': 1.0}, {'intent_joke': 1.0, 'prev_action_joke': 1.0}]
There is a memorised next action '0'
Predicted next action using policy_0_MemoizationPolicy
Predicted next action 'action_listen' with prob 1.00.
Action 'action_listen' ended with events '[]'
Recreating tracker for id 'default'
C:\Users\AndresArciniegas\AppData\Roaming\Python\Python36\site-packages\sklearn\preprocessing\label.py:151: DeprecationWarning: The truth value of an empty array is ambiguous. Returning False, but in future this will result in an error. Use `array.size > 0` to check that an array is not empty.
  if diff:

Received user message 'Tell me another joke' with intent '{'name': 'joke', 'confidence': 0.3882084444679357}' and entities '[]'
Logged UserUtterance - tracker now has 10 events
Current slot values: 
	location: None
	object: None
Current tracker state [{'intent_joke': 1.0, 'prev_action_joke': 1.0}, {'prev_action_listen': 1.0, 'intent_joke': 1.0}]
There is a memorised next action '9'
Predicted next action using policy_0_MemoizationPolicy
Predicted next action 'action_joke' with prob 1.00.
Calling action endpoint to run action 'action_joke'.
Failed to run custom action 'action_joke'. Couldn't connect to the server at 'http://localhost:5055/webhook'. Is the server running? Error: HTTPConnectionPool(host='localhost', port=5055): Max retries exceeded with url: /webhook (Caused by NewConnectionError('<urllib3.connection.HTTPConnection object at 0x00000156699804A8>: Failed to establish a new connection: [WinError 10061] No connection could be made because the target machine actively refused it',))
Encountered an exception while running action 'action_joke'. Bot will continue, but the actions events are lost. Make sure to fix the exception in your custom code.
Failed to execute custom action.
Traceback (most recent call last):
  File "D:\ProgramFiles\Anaconda3\envs\envbot\lib\site-packages\urllib3\connection.py", line 171, in _new_conn
    (self._dns_host, self.port), self.timeout, **extra_kw)
  File "D:\ProgramFiles\Anaconda3\envs\envbot\lib\site-packages\urllib3\util\connection.py", line 79, in create_connection
    raise err
  File "D:\ProgramFiles\Anaconda3\envs\envbot\lib\site-packages\urllib3\util\connection.py", line 69, in create_connection
    sock.connect(sa)
ConnectionRefusedError: [WinError 10061] No connection could be made because the target machine actively refused it

During handling of the above exception, another exception occurred:

Traceback (most recent call last):
  File "D:\ProgramFiles\Anaconda3\envs\envbot\lib\site-packages\urllib3\connectionpool.py", line 600, in urlopen
    chunked=chunked)
  File "D:\ProgramFiles\Anaconda3\envs\envbot\lib\site-packages\urllib3\connectionpool.py", line 354, in _make_request
    conn.request(method, url, **httplib_request_kw)
  File "D:\ProgramFiles\Anaconda3\envs\envbot\lib\http\client.py", line 1239, in request
    self._send_request(method, url, body, headers, encode_chunked)
  File "D:\ProgramFiles\Anaconda3\envs\envbot\lib\http\client.py", line 1285, in _send_request
    self.endheaders(body, encode_chunked=encode_chunked)
  File "D:\ProgramFiles\Anaconda3\envs\envbot\lib\http\client.py", line 1234, in endheaders
    self._send_output(message_body, encode_chunked=encode_chunked)
  File "D:\ProgramFiles\Anaconda3\envs\envbot\lib\http\client.py", line 1026, in _send_output
    self.send(msg)
  File "D:\ProgramFiles\Anaconda3\envs\envbot\lib\http\client.py", line 964, in send
    self.connect()
  File "D:\ProgramFiles\Anaconda3\envs\envbot\lib\site-packages\urllib3\connection.py", line 196, in connect
    conn = self._new_conn()
  File "D:\ProgramFiles\Anaconda3\envs\envbot\lib\site-packages\urllib3\connection.py", line 180, in _new_conn
    self, "Failed to establish a new connection: %s" % e)
urllib3.exceptions.NewConnectionError: <urllib3.connection.HTTPConnection object at 0x00000156699804A8>: Failed to establish a new connection: [WinError 10061] No connection could be made because the target machine actively refused it

During handling of the above exception, another exception occurred:

Traceback (most recent call last):
  File "D:\ProgramFiles\Anaconda3\envs\envbot\lib\site-packages\requests\adapters.py", line 449, in send
    timeout=timeout
  File "D:\ProgramFiles\Anaconda3\envs\envbot\lib\site-packages\urllib3\connectionpool.py", line 638, in urlopen
    _stacktrace=sys.exc_info()[2])
  File "D:\ProgramFiles\Anaconda3\envs\envbot\lib\site-packages\urllib3\util\retry.py", line 398, in increment
    raise MaxRetryError(_pool, url, error or ResponseError(cause))
urllib3.exceptions.MaxRetryError: HTTPConnectionPool(host='localhost', port=5055): Max retries exceeded with url: /webhook (Caused by NewConnectionError('<urllib3.connection.HTTPConnection object at 0x00000156699804A8>: Failed to establish a new connection: [WinError 10061] No connection could be made because the target machine actively refused it',))

During handling of the above exception, another exception occurred:

Traceback (most recent call last):
  File "C:\Users\AndresArciniegas\AppData\Roaming\Python\Python36\site-packages\rasa_core\actions\action.py", line 327, in run
    json=json, method="post", timeout=DEFAULT_REQUEST_TIMEOUT)
  File "C:\Users\AndresArciniegas\AppData\Roaming\Python\Python36\site-packages\rasa_core\utils.py", line 748, in request
    **kwargs)
  File "D:\ProgramFiles\Anaconda3\envs\envbot\lib\site-packages\requests\api.py", line 60, in request
    return session.request(method=method, url=url, **kwargs)
  File "D:\ProgramFiles\Anaconda3\envs\envbot\lib\site-packages\requests\sessions.py", line 524, in request
    resp = self.send(prep, **send_kwargs)
  File "D:\ProgramFiles\Anaconda3\envs\envbot\lib\site-packages\requests\sessions.py", line 637, in send
    r = adapter.send(request, **kwargs)
  File "D:\ProgramFiles\Anaconda3\envs\envbot\lib\site-packages\requests\adapters.py", line 516, in send
    raise ConnectionError(e, request=request)
requests.exceptions.ConnectionError: HTTPConnectionPool(host='localhost', port=5055): Max retries exceeded with url: /webhook (Caused by NewConnectionError('<urllib3.connection.HTTPConnection object at 0x00000156699804A8>: Failed to establish a new connection: [WinError 10061] No connection could be made because the target machine actively refused it',))

During handling of the above exception, another exception occurred:

Traceback (most recent call last):
  File "C:\Users\AndresArciniegas\AppData\Roaming\Python\Python36\site-packages\rasa_core\processor.py", line 351, in _run_action
    events = action.run(dispatcher, tracker, self.domain)
  File "C:\Users\AndresArciniegas\AppData\Roaming\Python\Python36\site-packages\rasa_core\actions\action.py", line 348, in run
    raise Exception("Failed to execute custom action.")
Exception: Failed to execute custom action.
Action 'action_joke' ended with events '[]'
Current tracker state [{'prev_action_listen': 1.0, 'intent_joke': 1.0}, {'intent_joke': 1.0, 'prev_action_joke': 1.0}]
There is a memorised next action '0'
Predicted next action using policy_0_MemoizationPolicy
Predicted next action 'action_listen' with prob 1.00.
Action 'action_listen' ended with events '[]'
Rasa process starting
Added 'nlp_spacy' to component cache. Key 'nlp_spacy-en'.
C:\Users\AndresArciniegas\AppData\Roaming\Python\Python36\site-packages\rasa_nlu\extractors\entity_synonyms.py:85: UserWarning: Failed to load synonyms file from 'models/nlu/default/nursenlu\entity_synonyms.json'
  "".format(entity_synonyms_file))

D:\ProgramFiles\Anaconda3\envs\envbot\lib\site-packages\pykwalify\core.py:99: UnsafeLoaderWarning: 
The default 'Loader' for 'load(stream)' without further arguments can be unsafe.
Use 'load(stream, Loader=ruamel.yaml.Loader)' explicitly if that is OK.
Alternatively include the following in your code:

  import warnings
  warnings.simplefilter('ignore', ruamel.yaml.error.UnsafeLoaderWarning)

In most other cases you should consider using 'safe_load(stream)'
  data = yaml.load(stream)

Available web server routes: 
static                                             HEAD, OPTIONS, GET             /static/[filename]
custom_webhook_CmdlineInput.health                 HEAD, OPTIONS, GET             /webhooks/rest/
custom_webhook_CmdlineInput.receive                OPTIONS, POST                  /webhooks/rest/webhook
Rasa Core server is up and running on http://localhost:5005
Rasa process starting
Added 'nlp_spacy' to component cache. Key 'nlp_spacy-en'.
C:\Users\AndresArciniegas\AppData\Roaming\Python\Python36\site-packages\rasa_nlu\extractors\entity_synonyms.py:85: UserWarning: Failed to load synonyms file from 'models/nlu/default/nursenlu\entity_synonyms.json'
  "".format(entity_synonyms_file))

D:\ProgramFiles\Anaconda3\envs\envbot\lib\site-packages\pykwalify\core.py:99: UnsafeLoaderWarning: 
The default 'Loader' for 'load(stream)' without further arguments can be unsafe.
Use 'load(stream, Loader=ruamel.yaml.Loader)' explicitly if that is OK.
Alternatively include the following in your code:

  import warnings
  warnings.simplefilter('ignore', ruamel.yaml.error.UnsafeLoaderWarning)

In most other cases you should consider using 'safe_load(stream)'
  data = yaml.load(stream)

Available web server routes: 
static                                             HEAD, OPTIONS, GET             /static/[filename]
custom_webhook_CmdlineInput.health                 HEAD, OPTIONS, GET             /webhooks/rest/
custom_webhook_CmdlineInput.receive                POST, OPTIONS                  /webhooks/rest/webhook
Rasa Core server is up and running on http://localhost:5005
Creating a new tracker for id 'default'.
C:\Users\AndresArciniegas\AppData\Roaming\Python\Python36\site-packages\sklearn\preprocessing\label.py:151: DeprecationWarning: The truth value of an empty array is ambiguous. Returning False, but in future this will result in an error. Use `array.size > 0` to check that an array is not empty.
  if diff:

Received user message 'Hello' with intent '{'name': 'greet', 'confidence': 0.6280013948232969}' and entities '[]'
Logged UserUtterance - tracker now has 2 events
Current slot values: 
	location: None
	object: None
Current tracker state [{}, {'prev_action_listen': 1.0, 'intent_greet': 1.0}]
There is a memorised next action '5'
Predicted next action using policy_0_MemoizationPolicy
Predicted next action 'utter_greet' with prob 1.00.
Action 'utter_greet' ended with events '[]'
Bot utterance 'BotUttered(text: Greetings. You can call me Nurse. How may I help you?, data: {
  "elements": null,
  "buttons": null,
  "attachment": null
})'
Current tracker state [{'prev_action_listen': 1.0, 'intent_greet': 1.0}, {'prev_utter_greet': 1.0, 'intent_greet': 1.0}]
There is a memorised next action '0'
Predicted next action using policy_0_MemoizationPolicy
Predicted next action 'action_listen' with prob 1.00.
Action 'action_listen' ended with events '[]'
Recreating tracker for id 'default'
C:\Users\AndresArciniegas\AppData\Roaming\Python\Python36\site-packages\sklearn\preprocessing\label.py:151: DeprecationWarning: The truth value of an empty array is ambiguous. Returning False, but in future this will result in an error. Use `array.size > 0` to check that an array is not empty.
  if diff:

Received user message 'Tell me a joke' with intent '{'name': 'joke', 'confidence': 0.6094320004912319}' and entities '[]'
Logged UserUtterance - tracker now has 6 events
Current slot values: 
	location: None
	object: None
Current tracker state [{'prev_utter_greet': 1.0, 'intent_greet': 1.0}, {'prev_action_listen': 1.0, 'intent_joke': 1.0}]
There is a memorised next action '9'
Predicted next action using policy_0_MemoizationPolicy
Predicted next action 'action_joke' with prob 1.00.
Calling action endpoint to run action 'action_joke'.
Action 'action_joke' ended with events '[]'
Bot utterance 'BotUttered(text: Chuck norris can jump rope with steel pipe. OH he also plays frisbee golf with discuss!, data: {
  "elements": null,
  "buttons": null,
  "attachment": null
})'
Current tracker state [{'prev_action_listen': 1.0, 'intent_joke': 1.0}, {'intent_joke': 1.0, 'prev_action_joke': 1.0}]
There is a memorised next action '0'
Predicted next action using policy_0_MemoizationPolicy
Predicted next action 'action_listen' with prob 1.00.
Action 'action_listen' ended with events '[]'
Recreating tracker for id 'default'
C:\Users\AndresArciniegas\AppData\Roaming\Python\Python36\site-packages\sklearn\preprocessing\label.py:151: DeprecationWarning: The truth value of an empty array is ambiguous. Returning False, but in future this will result in an error. Use `array.size > 0` to check that an array is not empty.
  if diff:

Received user message 'Tell me a joke' with intent '{'name': 'joke', 'confidence': 0.6094320004912319}' and entities '[]'
Logged UserUtterance - tracker now has 10 events
Current slot values: 
	location: None
	object: None
Current tracker state [{'intent_joke': 1.0, 'prev_action_joke': 1.0}, {'prev_action_listen': 1.0, 'intent_joke': 1.0}]
There is a memorised next action '9'
Predicted next action using policy_0_MemoizationPolicy
Predicted next action 'action_joke' with prob 1.00.
Calling action endpoint to run action 'action_joke'.
Action 'action_joke' ended with events '[]'
Bot utterance 'BotUttered(text: Chuck Norris can believe its not butter, data: {
  "elements": null,
  "buttons": null,
  "attachment": null
})'
Current tracker state [{'prev_action_listen': 1.0, 'intent_joke': 1.0}, {'intent_joke': 1.0, 'prev_action_joke': 1.0}]
There is a memorised next action '0'
Predicted next action using policy_0_MemoizationPolicy
Predicted next action 'action_listen' with prob 1.00.
Action 'action_listen' ended with events '[]'
Rasa process starting
Added 'nlp_spacy' to component cache. Key 'nlp_spacy-en'.
C:\Users\AndresArciniegas\AppData\Roaming\Python\Python36\site-packages\rasa_nlu\extractors\entity_synonyms.py:85: UserWarning: Failed to load synonyms file from 'models/nursebot/interpreter\entity_synonyms.json'
  "".format(entity_synonyms_file))

D:\ProgramFiles\Anaconda3\envs\bot\lib\site-packages\pykwalify\core.py:99: UnsafeLoaderWarning: 
The default 'Loader' for 'load(stream)' without further arguments can be unsafe.
Use 'load(stream, Loader=ruamel.yaml.Loader)' explicitly if that is OK.
Alternatively include the following in your code:

  import warnings
  warnings.simplefilter('ignore', ruamel.yaml.error.UnsafeLoaderWarning)

In most other cases you should consider using 'safe_load(stream)'
  data = yaml.load(stream)

Available web server routes: 
static                                             GET, OPTIONS, HEAD             /static/[filename]
custom_webhook_CmdlineInput.health                 GET, OPTIONS, HEAD             /webhooks/rest/
custom_webhook_CmdlineInput.receive                POST, OPTIONS                  /webhooks/rest/webhook
Rasa Core server is up and running on http://localhost:5005
Rasa process starting
Added 'nlp_spacy' to component cache. Key 'nlp_spacy-en'.
C:\Users\AndresArciniegas\AppData\Roaming\Python\Python36\site-packages\rasa_nlu\extractors\entity_synonyms.py:85: UserWarning: Failed to load synonyms file from 'models/nursebot/interpreter\entity_synonyms.json'
  "".format(entity_synonyms_file))

D:\ProgramFiles\Anaconda3\envs\bot\lib\site-packages\pykwalify\core.py:99: UnsafeLoaderWarning: 
The default 'Loader' for 'load(stream)' without further arguments can be unsafe.
Use 'load(stream, Loader=ruamel.yaml.Loader)' explicitly if that is OK.
Alternatively include the following in your code:

  import warnings
  warnings.simplefilter('ignore', ruamel.yaml.error.UnsafeLoaderWarning)

In most other cases you should consider using 'safe_load(stream)'
  data = yaml.load(stream)

Available web server routes: 
static                                             HEAD, OPTIONS, GET             /static/[filename]
custom_webhook_CmdlineInput.health                 HEAD, OPTIONS, GET             /webhooks/rest/
custom_webhook_CmdlineInput.receive                POST, OPTIONS                  /webhooks/rest/webhook
Rasa Core server is up and running on http://localhost:5005
Creating a new tracker for id 'default'.
D:\ProgramFiles\Anaconda3\envs\bot\lib\site-packages\sklearn\preprocessing\label.py:151: DeprecationWarning: The truth value of an empty array is ambiguous. Returning False, but in future this will result in an error. Use `array.size > 0` to check that an array is not empty.
  if diff:

Received user message 'Hello' with intent '{'name': 'greet', 'confidence': 0.6896984815787254}' and entities '[]'
Logged UserUtterance - tracker now has 2 events
Current slot values: 
	object: None
	place: None
Current tracker state [None, None, None, {}, {'intent_greet': 1.0, 'prev_action_listen': 1.0}]
There is a memorised next action '5'
Predicted next action using policy_0_MemoizationPolicy
Predicted next action 'utter_greet' with prob 1.00.
Action 'utter_greet' ended with events '[]'
Bot utterance 'BotUttered(text: Hi human. You can call me Nurse. How may I help you?, data: {
  "elements": null,
  "buttons": null,
  "attachment": null
})'
Current tracker state [None, None, {}, {'intent_greet': 1.0, 'prev_action_listen': 1.0}, {'intent_greet': 1.0, 'prev_utter_greet': 1.0}]
There is a memorised next action '0'
Predicted next action using policy_0_MemoizationPolicy
Predicted next action 'action_listen' with prob 1.00.
Action 'action_listen' ended with events '[]'
Recreating tracker for id 'default'
D:\ProgramFiles\Anaconda3\envs\bot\lib\site-packages\sklearn\preprocessing\label.py:151: DeprecationWarning: The truth value of an empty array is ambiguous. Returning False, but in future this will result in an error. Use `array.size > 0` to check that an array is not empty.
  if diff:

Received user message 'I do not feel good' with intent '{'name': 'goodbye', 'confidence': 0.5709773539798191}' and entities '[]'
Logged UserUtterance - tracker now has 6 events
Current slot values: 
	object: None
	place: None
Current tracker state [None, {}, {'intent_greet': 1.0, 'prev_action_listen': 1.0}, {'intent_greet': 1.0, 'prev_utter_greet': 1.0}, {'intent_goodbye': 1.0, 'prev_action_listen': 1.0}]
There is a memorised next action '4'
Predicted next action using policy_0_MemoizationPolicy
Predicted next action 'utter_standby' with prob 1.00.
Action 'utter_standby' ended with events '[]'
Bot utterance 'BotUttered(text: I'll be here if you need me., data: {
  "elements": null,
  "buttons": null,
  "attachment": null
})'
Current tracker state [{}, {'intent_greet': 1.0, 'prev_action_listen': 1.0}, {'intent_greet': 1.0, 'prev_utter_greet': 1.0}, {'intent_goodbye': 1.0, 'prev_action_listen': 1.0}, {'intent_goodbye': 1.0, 'prev_utter_standby': 1.0}]
There is a memorised next action '0'
Predicted next action using policy_0_MemoizationPolicy
Predicted next action 'action_listen' with prob 1.00.
Action 'action_listen' ended with events '[]'
Recreating tracker for id 'default'
D:\ProgramFiles\Anaconda3\envs\bot\lib\site-packages\sklearn\preprocessing\label.py:151: DeprecationWarning: The truth value of an empty array is ambiguous. Returning False, but in future this will result in an error. Use `array.size > 0` to check that an array is not empty.
  if diff:

Received user message 'Take me to the bathroom' with intent '{'name': 'move', 'confidence': 0.8635418823290931}' and entities '[{'start': 15, 'end': 23, 'value': 'bathroom', 'entity': 'place', 'confidence': 0.9644786106641832, 'extractor': 'ner_crf'}]'
Logged UserUtterance - tracker now has 11 events
Current slot values: 
	object: None
	place: bathroom
Current tracker state [{'intent_greet': 1.0, 'prev_action_listen': 1.0}, {'intent_greet': 1.0, 'prev_utter_greet': 1.0}, {'intent_goodbye': 1.0, 'prev_action_listen': 1.0}, {'intent_goodbye': 1.0, 'prev_utter_standby': 1.0}, {'intent_move': 1.0, 'prev_action_listen': 1.0, 'slot_place_0': 1.0, 'entity_place': 1.0}]
There is no memorised next action
Predicted next action using policy_1_KerasPolicy
Predicted next action 'utter_move' with prob 1.00.
Action 'utter_move' ended with events '[]'
Bot utterance 'BotUttered(text: Sure, let me help you., data: {
  "elements": null,
  "buttons": null,
  "attachment": null
})'
Current tracker state [{'intent_greet': 1.0, 'prev_utter_greet': 1.0}, {'intent_goodbye': 1.0, 'prev_action_listen': 1.0}, {'intent_goodbye': 1.0, 'prev_utter_standby': 1.0}, {'intent_move': 1.0, 'prev_action_listen': 1.0, 'slot_place_0': 1.0, 'entity_place': 1.0}, {'intent_move': 1.0, 'prev_utter_move': 1.0, 'slot_place_0': 1.0, 'entity_place': 1.0}]
There is no memorised next action
Predicted next action using policy_1_KerasPolicy
Predicted next action 'utter_somethingelse' with prob 1.00.
Action 'utter_somethingelse' ended with events '[]'
Bot utterance 'BotUttered(text: Do you need anything else?, data: {
  "elements": null,
  "buttons": null,
  "attachment": null
})'
Current tracker state [{'intent_goodbye': 1.0, 'prev_action_listen': 1.0}, {'intent_goodbye': 1.0, 'prev_utter_standby': 1.0}, {'intent_move': 1.0, 'prev_action_listen': 1.0, 'slot_place_0': 1.0, 'entity_place': 1.0}, {'intent_move': 1.0, 'prev_utter_move': 1.0, 'slot_place_0': 1.0, 'entity_place': 1.0}, {'intent_move': 1.0, 'prev_utter_somethingelse': 1.0, 'slot_place_0': 1.0, 'entity_place': 1.0}]
There is a memorised next action '0'
Predicted next action using policy_0_MemoizationPolicy
Predicted next action 'action_listen' with prob 1.00.
Action 'action_listen' ended with events '[]'
Recreating tracker for id 'default'
D:\ProgramFiles\Anaconda3\envs\bot\lib\site-packages\sklearn\preprocessing\label.py:151: DeprecationWarning: The truth value of an empty array is ambiguous. Returning False, but in future this will result in an error. Use `array.size > 0` to check that an array is not empty.
  if diff:

Received user message 'Bring me the remote' with intent '{'name': 'reach', 'confidence': 0.7279796076039241}' and entities '[{'start': 13, 'end': 19, 'value': 'remote', 'entity': 'object', 'confidence': 0.9129487203367502, 'extractor': 'ner_crf'}]'
Logged UserUtterance - tracker now has 18 events
Current slot values: 
	object: remote
	place: bathroom
Current tracker state [{'intent_goodbye': 1.0, 'prev_utter_standby': 1.0}, {'intent_move': 1.0, 'prev_action_listen': 1.0, 'slot_place_0': 1.0, 'entity_place': 1.0}, {'intent_move': 1.0, 'prev_utter_move': 1.0, 'slot_place_0': 1.0, 'entity_place': 1.0}, {'intent_move': 1.0, 'prev_utter_somethingelse': 1.0, 'slot_place_0': 1.0, 'entity_place': 1.0}, {'prev_action_listen': 1.0, 'intent_reach': 1.0, 'slot_place_0': 1.0, 'slot_object_0': 1.0, 'entity_object': 1.0}]
There is no memorised next action
Predicted next action using policy_1_KerasPolicy
Predicted next action 'utter_reach' with prob 1.00.
Action 'utter_reach' ended with events '[]'
Bot utterance 'BotUttered(text: Of course! There you go., data: {
  "elements": null,
  "buttons": null,
  "attachment": null
})'
Current tracker state [{'intent_move': 1.0, 'prev_action_listen': 1.0, 'slot_place_0': 1.0, 'entity_place': 1.0}, {'intent_move': 1.0, 'prev_utter_move': 1.0, 'slot_place_0': 1.0, 'entity_place': 1.0}, {'intent_move': 1.0, 'prev_utter_somethingelse': 1.0, 'slot_place_0': 1.0, 'entity_place': 1.0}, {'prev_action_listen': 1.0, 'intent_reach': 1.0, 'slot_place_0': 1.0, 'slot_object_0': 1.0, 'entity_object': 1.0}, {'prev_utter_reach': 1.0, 'intent_reach': 1.0, 'slot_place_0': 1.0, 'slot_object_0': 1.0, 'entity_object': 1.0}]
There is a memorised next action '0'
Predicted next action using policy_0_MemoizationPolicy
Predicted next action 'action_listen' with prob 1.00.
Action 'action_listen' ended with events '[]'
